Workbook

Sheet Tablero
A1: TABLERO DE CARTERA: ¿A QUIÉN LLAMO ESTA SEMANA?
A2: Datos ficticios. Un tablero sirve si responde una pregunta y propone una acción: aquí, qué familias requieren contacto y de qué tipo.
B3: Fecha de corte | C3: 46295 | E3: Meta de recaudo del mes | G3: 0.9 | I3: Umbral de saldo para priorizar | K3: 1000000 | M3: Mes | N3: % recaudo | O3: Meta
M4: Abr | N4: 0.93 | O4: =$G$3
B5: Facturado del mes | D5: Recaudado del mes | F5: % de recaudo | H5: Cartera vencida total | J5: Familias con mora > 60 días | M5: May | N5: 0.91 | O5: =$G$3
B6: =SUM(Datos!C4:C83) | D6: =SUM(Datos!C4:C83)-SUMIFS(Datos!C4:C83,Datos!G4:G83,"<>Al día") | F6: =IF(B6=0,0,D6/B6) | H6: =SUM(Datos!D4:D83) | J6: =COUNTIFS(Datos!F4:F83,">60") | M6: Jun | N6: 0.88 | O6: =$G$3
F7: =IF(F6>=G3,"En meta",IF(F6>=G3-0.05,"Cerca de la meta","Por debajo de la meta")) | M7: Jul | N7: 0.9 | O7: =$G$3
M8: Ago | N8: 0.86 | O8: =$G$3
B9: Cartera por rango de mora | G9: Diez saldos más altos y qué hacer | M9: Sep | N9: =F6 | O9: =$G$3
B10: Rango | C10: Saldo | D10: Familias | E10: % del saldo | G10: # | H10: Familia | I10: Saldo | J10: Días de mora | K10: Acción sugerida
B11: 1-30 días | C11: =SUMIFS(Datos!$D$4:$D$83,Datos!$G$4:$G$83,B11) | D11: =COUNTIFS(Datos!$G$4:$G$83,B11) | E11: =IF($C$15=0,0,C11/$C$15) | G11: 1 | H11: =INDEX(Datos!$A$4:$A$83,MATCH(LARGE(Datos!$I$4:$I$83,G11),Datos!$I$4:$I$83,0)) | I11: =INDEX(Datos!$D$4:$D$83,MATCH(LARGE(Datos!$I$4:$I$83,G11),Datos!$I$4:$I$83,0)) | J11: =INDEX(Datos!$F$4:$F$83,MATCH(LARGE(Datos!$I$4:$I$83,G11),Datos!$I$4:$I$83,0)) | K11: =INDEX(Datos!$H$4:$H$83,MATCH(LARGE(Datos!$I$4:$I$83,G11),Datos!$I$4:$I$83,0))
B12: 31-60 días | C12: =SUMIFS(Datos!$D$4:$D$83,Datos!$G$4:$G$83,B12) | D12: =COUNTIFS(Datos!$G$4:$G$83,B12) | E12: =IF($C$15=0,0,C12/$C$15) | G12: 2 | H12: =INDEX(Datos!$A$4:$A$83,MATCH(LARGE(Datos!$I$4:$I$83,G12),Datos!$I$4:$I$83,0)) | I12: =INDEX(Datos!$D$4:$D$83,MATCH(LARGE(Datos!$I$4:$I$83,G12),Datos!$I$4:$I$83,0)) | J12: =INDEX(Datos!$F$4:$F$83,MATCH(LARGE(Datos!$I$4:$I$83,G12),Datos!$I$4:$I$83,0)) | K12: =INDEX(Datos!$H$4:$H$83,MATCH(LARGE(Datos!$I$4:$I$83,G12),Datos!$I$4:$I$83,0))
B13: 61-90 días | C13: =SUMIFS(Datos!$D$4:$D$83,Datos!$G$4:$G$83,B13) | D13: =COUNTIFS(Datos!$G$4:$G$83,B13) | E13: =IF($C$15=0,0,C13/$C$15) | G13: 3 | H13: =INDEX(Datos!$A$4:$A$83,MATCH(LARGE(Datos!$I$4:$I$83,G13),Datos!$I$4:$I$83,0)) | I13: =INDEX(Datos!$D$4:$D$83,MATCH(LARGE(Datos!$I$4:$I$83,G13),Datos!$I$4:$I$83,0)) | J13: =INDEX(Datos!$F$4:$F$83,MATCH(LARGE(Datos!$I$4:$I$83,G13),Datos!$I$4:$I$83,0)) | K13: =INDEX(Datos!$H$4:$H$83,MATCH(LARGE(Datos!$I$4:$I$83,G13),Datos!$I$4:$I$83,0))
B14: Más de 90 días | C14: =SUMIFS(Datos!$D$4:$D$83,Datos!$G$4:$G$83,B14) | D14: =COUNTIFS(Datos!$G$4:$G$83,B14) | E14: =IF($C$15=0,0,C14/$C$15) | G14: 4 | H14: =INDEX(Datos!$A$4:$A$83,MATCH(LARGE(Datos!$I$4:$I$83,G14),Datos!$I$4:$I$83,0)) | I14: =INDEX(Datos!$D$4:$D$83,MATCH(LARGE(Datos!$I$4:$I$83,G14),Datos!$I$4:$I$83,0)) | J14: =INDEX(Datos!$F$4:$F$83,MATCH(LARGE(Datos!$I$4:$I$83,G14),Datos!$I$4:$I$83,0)) | K14: =INDEX(Datos!$H$4:$H$83,MATCH(LARGE(Datos!$I$4:$I$83,G14),Datos!$I$4:$I$83,0))
B15: Total | C15: =SUM(C11:C14) | D15: =SUM(D11:D14) | E15: =SUM(E11:E14) | G15: 5 | H15: =INDEX(Datos!$A$4:$A$83,MATCH(LARGE(Datos!$I$4:$I$83,G15),Datos!$I$4:$I$83,0)) | I15: =INDEX(Datos!$D$4:$D$83,MATCH(LARGE(Datos!$I$4:$I$83,G15),Datos!$I$4:$I$83,0)) | J15: =INDEX(Datos!$F$4:$F$83,MATCH(LARGE(Datos!$I$4:$I$83,G15),Datos!$I$4:$I$83,0)) | K15: =INDEX(Datos!$H$4:$H$83,MATCH(LARGE(Datos!$I$4:$I$83,G15),Datos!$I$4:$I$83,0))
G16: 6 | H16: =INDEX(Datos!$A$4:$A$83,MATCH(LARGE(Datos!$I$4:$I$83,G16),Datos!$I$4:$I$83,0)) | I16: =INDEX(Datos!$D$4:$D$83,MATCH(LARGE(Datos!$I$4:$I$83,G16),Datos!$I$4:$I$83,0)) | J16: =INDEX(Datos!$F$4:$F$83,MATCH(LARGE(Datos!$I$4:$I$83,G16),Datos!$I$4:$I$83,0)) | K16: =INDEX(Datos!$H$4:$H$83,MATCH(LARGE(Datos!$I$4:$I$83,G16),Datos!$I$4:$I$83,0))
B17: Prioridad esta semana | G17: 7 | H17: =INDEX(Datos!$A$4:$A$83,MATCH(LARGE(Datos!$I$4:$I$83,G17),Datos!$I$4:$I$83,0)) | I17: =INDEX(Datos!$D$4:$D$83,MATCH(LARGE(Datos!$I$4:$I$83,G17),Datos!$I$4:$I$83,0)) | J17: =INDEX(Datos!$F$4:$F$83,MATCH(LARGE(Datos!$I$4:$I$83,G17),Datos!$I$4:$I$83,0)) | K17: =INDEX(Datos!$H$4:$H$83,MATCH(LARGE(Datos!$I$4:$I$83,G17),Datos!$I$4:$I$83,0))
B18: Familias con mora de 61 a 90 días y saldo mayor o igual al umbral | G18: 8 | H18: =COUNTIFS(Datos!F4:F83,">60",Datos!F4:F83,"<=90",Datos!D4:D83,">="&K3) | I18: =INDEX(Datos!$D$4:$D$83,MATCH(LARGE(Datos!$I$4:$I$83,G18),Datos!$I$4:$I$83,0)) | J18: =INDEX(Datos!$F$4:$F$83,MATCH(LARGE(Datos!$I$4:$I$83,G18),Datos!$I$4:$I$83,0)) | K18: =INDEX(Datos!$H$4:$H$83,MATCH(LARGE(Datos!$I$4:$I$83,G18),Datos!$I$4:$I$83,0))
B19: Familias con mora de más de 90 días (reunión para acuerdo de pago) | G19: 9 | H19: =COUNTIFS(Datos!F4:F83,">90") | I19: =INDEX(Datos!$D$4:$D$83,MATCH(LARGE(Datos!$I$4:$I$83,G19),Datos!$I$4:$I$83,0)) | J19: =INDEX(Datos!$F$4:$F$83,MATCH(LARGE(Datos!$I$4:$I$83,G19),Datos!$I$4:$I$83,0)) | K19: =INDEX(Datos!$H$4:$H$83,MATCH(LARGE(Datos!$I$4:$I$83,G19),Datos!$I$4:$I$83,0))
B20: Saldo de las familias con mora de más de 60 días | G20: 10 | H20: =SUMIFS(Datos!D4:D83,Datos!F4:F83,">60") | I20: =INDEX(Datos!$D$4:$D$83,MATCH(LARGE(Datos!$I$4:$I$83,G20),Datos!$I$4:$I$83,0)) | J20: =INDEX(Datos!$F$4:$F$83,MATCH(LARGE(Datos!$I$4:$I$83,G20),Datos!$I$4:$I$83,0)) | K20: =INDEX(Datos!$H$4:$H$83,MATCH(LARGE(Datos!$I$4:$I$83,G20),Datos!$I$4:$I$83,0))
B21: % de la cartera concentrada en mora de más de 60 días | H21: =IF(C15=0,0,H20/C15)
B23: Las acciones son sugerencias para empezar una conversación respetuosa con la familia; ninguna reemplaza el criterio de la institución ni sus reglas de cobro.

Sheet Datos
A1: CARTERA DE PENSIONES (datos ficticios de un colegio) · fecha de corte en Tablero!C3
A3: Familia | B3: Estudiantes | C3: Valor mensual | D3: Saldo pendiente | E3: Fecha de vencimiento | F3: Días de mora | G3: Rango de mora | H3: Acción sugerida | I3: Clave de orden
A4: Familia 01 | B4: 1 | C4: 450000 | D4: 0 | F4: =IF(D4=0,0,Tablero!$C$3-E4) | G4: =IF(D4=0,"Al día",IF(F4<=30,"1-30 días",IF(F4<=60,"31-60 días",IF(F4<=90,"61-90 días","Más de 90 días")))) | H4: =IF(D4=0,"Sin acción",IF(F4<=30,"Recordatorio automático",IF(F4<=60,"Recordatorio escrito personalizado",IF(F4<=90,"Llamar esta semana","Reunión para acuerdo de pago")))) | I4: =D4+ROW()/1000000
A5: Familia 02 | B5: 1 | C5: 420000 | D5: 0 | F5: =IF(D5=0,0,Tablero!$C$3-E5) | G5: =IF(D5=0,"Al día",IF(F5<=30,"1-30 días",IF(F5<=60,"31-60 días",IF(F5<=90,"61-90 días","Más de 90 días")))) | H5: =IF(D5=0,"Sin acción",IF(F5<=30,"Recordatorio automático",IF(F5<=60,"Recordatorio escrito personalizado",IF(F5<=90,"Llamar esta semana","Reunión para acuerdo de pago")))) | I5: =D5+ROW()/1000000
A6: Familia 03 | B6: 2 | C6: 960000 | D6: 0 | F6: =IF(D6=0,0,Tablero!$C$3-E6) | G6: =IF(D6=0,"Al día",IF(F6<=30,"1-30 días",IF(F6<=60,"31-60 días",IF(F6<=90,"61-90 días","Más de 90 días")))) | H6: =IF(D6=0,"Sin acción",IF(F6<=30,"Recordatorio automático",IF(F6<=60,"Recordatorio escrito personalizado",IF(F6<=90,"Llamar esta semana","Reunión para acuerdo de pago")))) | I6: =D6+ROW()/1000000
A7: Familia 04 | B7: 2 | C7: 960000 | D7: 0 | F7: =IF(D7=0,0,Tablero!$C$3-E7) | G7: =IF(D7=0,"Al día",IF(F7<=30,"1-30 días",IF(F7<=60,"31-60 días",IF(F7<=90,"61-90 días","Más de 90 días")))) | H7: =IF(D7=0,"Sin acción",IF(F7<=30,"Recordatorio automático",IF(F7<=60,"Recordatorio escrito personalizado",IF(F7<=90,"Llamar esta semana","Reunión para acuerdo de pago")))) | I7: =D7+ROW()/1000000
A8: Familia 05 | B8: 1 | C8: 450000 | D8: 0 | F8: =IF(D8=0,0,Tablero!$C$3-E8) | G8: =IF(D8=0,"Al día",IF(F8<=30,"1-30 días",IF(F8<=60,"31-60 días",IF(F8<=90,"61-90 días","Más de 90 días")))) | H8: =IF(D8=0,"Sin acción",IF(F8<=30,"Recordatorio automático",IF(F8<=60,"Recordatorio escrito personalizado",IF(F8<=90,"Llamar esta semana","Reunión para acuerdo de pago")))) | I8: =D8+ROW()/1000000
A9: Familia 06 | B9: 2 | C9: 840000 | D9: 0 | F9: =IF(D9=0,0,Tablero!$C$3-E9) | G9: =IF(D9=0,"Al día",IF(F9<=30,"1-30 días",IF(F9<=60,"31-60 días",IF(F9<=90,"61-90 días","Más de 90 días")))) | H9: =IF(D9=0,"Sin acción",IF(F9<=30,"Recordatorio automático",IF(F9<=60,"Recordatorio escrito personalizado",IF(F9<=90,"Llamar esta semana","Reunión para acuerdo de pago")))) | I9: =D9+ROW()/1000000
A10: Familia 07 | B10: 1 | C10: 480000 | D10: 2400000 | E10: 46165 | F10: =IF(D10=0,0,Tablero!$C$3-E10) | G10: =IF(D10=0,"Al día",IF(F10<=30,"1-30 días",IF(F10<=60,"31-60 días",IF(F10<=90,"61-90 días","Más de 90 días")))) | H10: =IF(D10=0,"Sin acción",IF(F10<=30,"Recordatorio automático",IF(F10<=60,"Recordatorio escrito personalizado",IF(F10<=90,"Llamar esta semana","Reunión para acuerdo de pago")))) | I10: =D10+ROW()/1000000
A11: Familia 08 | B11: 1 | C11: 450000 | D11: 0 | F11: =IF(D11=0,0,Tablero!$C$3-E11) | G11: =IF(D11=0,"Al día",IF(F11<=30,"1-30 días",IF(F11<=60,"31-60 días",IF(F11<=90,"61-90 días","Más de 90 días")))) | H11: =IF(D11=0,"Sin acción",IF(F11<=30,"Recordatorio automático",IF(F11<=60,"Recordatorio escrito personalizado",IF(F11<=90,"Llamar esta semana","Reunión para acuerdo de pago")))) | I11: =D11+ROW()/1000000
A12: Familia 09 | B12: 2 | C12: 900000 | D12: 0 | F12: =IF(D12=0,0,Tablero!$C$3-E12) | G12: =IF(D12=0,"Al día",IF(F12<=30,"1-30 días",IF(F12<=60,"31-60 días",IF(F12<=90,"61-90 días","Más de 90 días")))) | H12: =IF(D12=0,"Sin acción",IF(F12<=30,"Recordatorio automático",IF(F12<=60,"Recordatorio escrito personalizado",IF(F12<=90,"Llamar esta semana","Reunión para acuerdo de pago")))) | I12: =D12+ROW()/1000000
A13: Familia 10 | B13: 1 | C13: 420000 | D13: 0 | F13: =IF(D13=0,0,Tablero!$C$3-E13) | G13: =IF(D13=0,"Al día",IF(F13<=30,"1-30 días",IF(F13<=60,"31-60 días",IF(F13<=90,"61-90 días","Más de 90 días")))) | H13: =IF(D13=0,"Sin acción",IF(F13<=30,"Recordatorio automático",IF(F13<=60,"Recordatorio escrito personalizado",IF(F13<=90,"Llamar esta semana","Reunión para acuerdo de pago")))) | I13: =D13+ROW()/1000000
A14: Familia 11 | B14: 1 | C14: 420000 | D14: 0 | F14: =IF(D14=0,0,Tablero!$C$3-E14) | G14: =IF(D14=0,"Al día",IF(F14<=30,"1-30 días",IF(F14<=60,"31-60 días",IF(F14<=90,"61-90 días","Más de 90 días")))) | H14: =IF(D14=0,"Sin acción",IF(F14<=30,"Recordatorio automático",IF(F14<=60,"Recordatorio escrito personalizado",IF(F14<=90,"Llamar esta semana","Reunión para acuerdo de pago")))) | I14: =D14+ROW()/1000000
A15: Familia 12 | B15: 2 | C15: 960000 | D15: 0 | F15: =IF(D15=0,0,Tablero!$C$3-E15) | G15: =IF(D15=0,"Al día",IF(F15<=30,"1-30 días",IF(F15<=60,"31-60 días",IF(F15<=90,"61-90 días","Más de 90 días")))) | H15: =IF(D15=0,"Sin acción",IF(F15<=30,"Recordatorio automático",IF(F15<=60,"Recordatorio escrito personalizado",IF(F15<=90,"Llamar esta semana","Reunión para acuerdo de pago")))) | I15: =D15+ROW()/1000000
A16: Familia 13 | B16: 1 | C16: 420000 | D16: 420000 | E16: 46284 | F16: =IF(D16=0,0,Tablero!$C$3-E16) | G16: =IF(D16=0,"Al día",IF(F16<=30,"1-30 días",IF(F16<=60,"31-60 días",IF(F16<=90,"61-90 días","Más de 90 días")))) | H16: =IF(D16=0,"Sin acción",IF(F16<=30,"Recordatorio automático",IF(F16<=60,"Recordatorio escrito personalizado",IF(F16<=90,"Llamar esta semana","Reunión para acuerdo de pago")))) | I16: =D16+ROW()/1000000
A17: Familia 14 | B17: 3 | C17: 1350000 | D17: 1350000 | E17: 46287 | F17: =IF(D17=0,0,Tablero!$C$3-E17) | G17: =IF(D17=0,"Al día",IF(F17<=30,"1-30 días",IF(F17<=60,"31-60 días",IF(F17<=90,"61-90 días","Más de 90 días")))) | H17: =IF(D17=0,"Sin acción",IF(F17<=30,"Recordatorio automático",IF(F17<=60,"Recordatorio escrito personalizado",IF(F17<=90,"Llamar esta semana","Reunión para acuerdo de pago")))) | I17: =D17+ROW()/1000000
A18: Familia 15 | B18: 2 | C18: 900000 | D18: 900000 | E18: 46273 | F18: =IF(D18=0,0,Tablero!$C$3-E18) | G18: =IF(D18=0,"Al día",IF(F18<=30,"1-30 días",IF(F18<=60,"31-60 días",IF(F18<=90,"61-90 días","Más de 90 días")))) | H18: =IF(D18=0,"Sin acción",IF(F18<=30,"Recordatorio automático",IF(F18<=60,"Recordatorio escrito personalizado",IF(F18<=90,"Llamar esta semana","Reunión para acuerdo de pago")))) | I18: =D18+ROW()/1000000
A19: Familia 16 | B19: 1 | C19: 450000 | D19: 0 | F19: =IF(D19=0,0,Tablero!$C$3-E19) | G19: =IF(D19=0,"Al día",IF(F19<=30,"1-30 días",IF(F19<=60,"31-60 días",IF(F19<=90,"61-90 días","Más de 90 días")))) | H19: =IF(D19=0,"Sin acción",IF(F19<=30,"Recordatorio automático",IF(F19<=60,"Recordatorio escrito personalizado",IF(F19<=90,"Llamar esta semana","Reunión para acuerdo de pago")))) | I19: =D19+ROW()/1000000
A20: Familia 17 | B20: 2 | C20: 840000 | D20: 0 | F20: =IF(D20=0,0,Tablero!$C$3-E20) | G20: =IF(D20=0,"Al día",IF(F20<=30,"1-30 días",IF(F20<=60,"31-60 días",IF(F20<=90,"61-90 días","Más de 90 días")))) | H20: =IF(D20=0,"Sin acción",IF(F20<=30,"Recordatorio automático",IF(F20<=60,"Recordatorio escrito personalizado",IF(F20<=90,"Llamar esta semana","Reunión para acuerdo de pago")))) | I20: =D20+ROW()/1000000
A21: Familia 18 | B21: 2 | C21: 840000 | D21: 840000 | E21: 46278 | F21: =IF(D21=0,0,Tablero!$C$3-E21) | G21: =IF(D21=0,"Al día",IF(F21<=30,"1-30 días",IF(F21<=60,"31-60 días",IF(F21<=90,"61-90 días","Más de 90 días")))) | H21: =IF(D21=0,"Sin acción",IF(F21<=30,"Recordatorio automático",IF(F21<=60,"Recordatorio escrito personalizado",IF(F21<=90,"Llamar esta semana","Reunión para acuerdo de pago")))) | I21: =D21+ROW()/1000000
A22: Familia 19 | B22: 2 | C22: 960000 | D22: 0 | F22: =IF(D22=0,0,Tablero!$C$3-E22) | G22: =IF(D22=0,"Al día",IF(F22<=30,"1-30 días",IF(F22<=60,"31-60 días",IF(F22<=90,"61-90 días","Más de 90 días")))) | H22: =IF(D22=0,"Sin acción",IF(F22<=30,"Recordatorio automático",IF(F22<=60,"Recordatorio escrito personalizado",IF(F22<=90,"Llamar esta semana","Reunión para acuerdo de pago")))) | I22: =D22+ROW()/1000000
A23: Familia 20 | B23: 1 | C23: 480000 | D23: 0 | F23: =IF(D23=0,0,Tablero!$C$3-E23) | G23: =IF(D23=0,"Al día",IF(F23<=30,"1-30 días",IF(F23<=60,"31-60 días",IF(F23<=90,"61-90 días","Más de 90 días")))) | H23: =IF(D23=0,"Sin acción",IF(F23<=30,"Recordatorio automático",IF(F23<=60,"Recordatorio escrito personalizado",IF(F23<=90,"Llamar esta semana","Reunión para acuerdo de pago")))) | I23: =D23+ROW()/1000000
A24: Familia 21 | B24: 3 | C24: 1260000 | D24: 0 | F24: =IF(D24=0,0,Tablero!$C$3-E24) | G24: =IF(D24=0,"Al día",IF(F24<=30,"1-30 días",IF(F24<=60,"31-60 días",IF(F24<=90,"61-90 días","Más de 90 días")))) | H24: =IF(D24=0,"Sin acción",IF(F24<=30,"Recordatorio automático",IF(F24<=60,"Recordatorio escrito personalizado",IF(F24<=90,"Llamar esta semana","Reunión para acuerdo de pago")))) | I24: =D24+ROW()/1000000
A25: Familia 22 | B25: 2 | C25: 840000 | D25: 2520000 | E25: 46229 | F25: =IF(D25=0,0,Tablero!$C$3-E25) | G25: =IF(D25=0,"Al día",IF(F25<=30,"1-30 días",IF(F25<=60,"31-60 días",IF(F25<=90,"61-90 días","Más de 90 días")))) | H25: =IF(D25=0,"Sin acción",IF(F25<=30,"Recordatorio automático",IF(F25<=60,"Recordatorio escrito personalizado",IF(F25<=90,"Llamar esta semana","Reunión para acuerdo de pago")))) | I25: =D25+ROW()/1000000
A26: Familia 23 | B26: 1 | C26: 450000 | D26: 0 | F26: =IF(D26=0,0,Tablero!$C$3-E26) | G26: =IF(D26=0,"Al día",IF(F26<=30,"1-30 días",IF(F26<=60,"31-60 días",IF(F26<=90,"61-90 días","Más de 90 días")))) | H26: =IF(D26=0,"Sin acción",IF(F26<=30,"Recordatorio automático",IF(F26<=60,"Recordatorio escrito personalizado",IF(F26<=90,"Llamar esta semana","Reunión para acuerdo de pago")))) | I26: =D26+ROW()/1000000
A27: Familia 24 | B27: 3 | C27: 1350000 | D27: 0 | F27: =IF(D27=0,0,Tablero!$C$3-E27) | G27: =IF(D27=0,"Al día",IF(F27<=30,"1-30 días",IF(F27<=60,"31-60 días",IF(F27<=90,"61-90 días","Más de 90 días")))) | H27: =IF(D27=0,"Sin acción",IF(F27<=30,"Recordatorio automático",IF(F27<=60,"Recordatorio escrito personalizado",IF(F27<=90,"Llamar esta semana","Reunión para acuerdo de pago")))) | I27: =D27+ROW()/1000000
A28: Familia 25 | B28: 2 | C28: 840000 | D28: 0 | F28: =IF(D28=0,0,Tablero!$C$3-E28) | G28: =IF(D28=0,"Al día",IF(F28<=30,"1-30 días",IF(F28<=60,"31-60 días",IF(F28<=90,"61-90 días","Más de 90 días")))) | H28: =IF(D28=0,"Sin acción",IF(F28<=30,"Recordatorio automático",IF(F28<=60,"Recordatorio escrito personalizado",IF(F28<=90,"Llamar esta semana","Reunión para acuerdo de pago")))) | I28: =D28+ROW()/1000000
A29: Familia 26 | B29: 2 | C29: 960000 | D29: 0 | F29: =IF(D29=0,0,Tablero!$C$3-E29) | G29: =IF(D29=0,"Al día",IF(F29<=30,"1-30 días",IF(F29<=60,"31-60 días",IF(F29<=90,"61-90 días","Más de 90 días")))) | H29: =IF(D29=0,"Sin acción",IF(F29<=30,"Recordatorio automático",IF(F29<=60,"Recordatorio escrito personalizado",IF(F29<=90,"Llamar esta semana","Reunión para acuerdo de pago")))) | I29: =D29+ROW()/1000000
A30: Familia 27 | B30: 1 | C30: 480000 | D30: 0 | F30: =IF(D30=0,0,Tablero!$C$3-E30) | G30: =IF(D30=0,"Al día",IF(F30<=30,"1-30 días",IF(F30<=60,"31-60 días",IF(F30<=90,"61-90 días","Más de 90 días")))) | H30: =IF(D30=0,"Sin acción",IF(F30<=30,"Recordatorio automático",IF(F30<=60,"Recordatorio escrito personalizado",IF(F30<=90,"Llamar esta semana","Reunión para acuerdo de pago")))) | I30: =D30+ROW()/1000000
A31: Familia 28 | B31: 3 | C31: 1440000 | D31: 0 | F31: =IF(D31=0,0,Tablero!$C$3-E31) | G31: =IF(D31=0,"Al día",IF(F31<=30,"1-30 días",IF(F31<=60,"31-60 días",IF(F31<=90,"61-90 días","Más de 90 días")))) | H31: =IF(D31=0,"Sin acción",IF(F31<=30,"Recordatorio automático",IF(F31<=60,"Recordatorio escrito personalizado",IF(F31<=90,"Llamar esta semana","Reunión para acuerdo de pago")))) | I31: =D31+ROW()/1000000
A32: Familia 29 | B32: 1 | C32: 480000 | D32: 0 | F32: =IF(D32=0,0,Tablero!$C$3-E32) | G32: =IF(D32=0,"Al día",IF(F32<=30,"1-30 días",IF(F32<=60,"31-60 días",IF(F32<=90,"61-90 días","Más de 90 días")))) | H32: =IF(D32=0,"Sin acción",IF(F32<=30,"Recordatorio automático",IF(F32<=60,"Recordatorio escrito personalizado",IF(F32<=90,"Llamar esta semana","Reunión para acuerdo de pago")))) | I32: =D32+ROW()/1000000
A33: Familia 30 | B33: 2 | C33: 900000 | D33: 1800000 | E33: 46247 | F33: =IF(D33=0,0,Tablero!$C$3-E33) | G33: =IF(D33=0,"Al día",IF(F33<=30,"1-30 días",IF(F33<=60,"31-60 días",IF(F33<=90,"61-90 días","Más de 90 días")))) | H33: =IF(D33=0,"Sin acción",IF(F33<=30,"Recordatorio automático",IF(F33<=60,"Recordatorio escrito personalizado",IF(F33<=90,"Llamar esta semana","Reunión para acuerdo de pago")))) | I33: =D33+ROW()/1000000
A34: Familia 31 | B34: 2 | C34: 840000 | D34: 0 | F34: =IF(D34=0,0,Tablero!$C$3-E34) | G34: =IF(D34=0,"Al día",IF(F34<=30,"1-30 días",IF(F34<=60,"31-60 días",IF(F34<=90,"61-90 días","Más de 90 días")))) | H34: =IF(D34=0,"Sin acción",IF(F34<=30,"Recordatorio automático",IF(F34<=60,"Recordatorio escrito personalizado",IF(F34<=90,"Llamar esta semana","Reunión para acuerdo de pago")))) | I34: =D34+ROW()/1000000
A35: Familia 32 | B35: 2 | C35: 840000 | D35: 0 | F35: =IF(D35=0,0,Tablero!$C$3-E35) | G35: =IF(D35=0,"Al día",IF(F35<=30,"1-30 días",IF(F35<=60,"31-60 días",IF(F35<=90,"61-90 días","Más de 90 días")))) | H35: =IF(D35=0,"Sin acción",IF(F35<=30,"Recordatorio automático",IF(F35<=60,"Recordatorio escrito personalizado",IF(F35<=90,"Llamar esta semana","Reunión para acuerdo de pago")))) | I35: =D35+ROW()/1000000
A36: Familia 33 | B36: 1 | C36: 480000 | D36: 0 | F36: =IF(D36=0,0,Tablero!$C$3-E36) | G36: =IF(D36=0,"Al día",IF(F36<=30,"1-30 días",IF(F36<=60,"31-60 días",IF(F36<=90,"61-90 días","Más de 90 días")))) | H36: =IF(D36=0,"Sin acción",IF(F36<=30,"Recordatorio automático",IF(F36<=60,"Recordatorio escrito personalizado",IF(F36<=90,"Llamar esta semana","Reunión para acuerdo de pago")))) | I36: =D36+ROW()/1000000
A37: Familia 34 | B37: 1 | C37: 480000 | D37: 960000 | E37: 46257 | F37: =IF(D37=0,0,Tablero!$C$3-E37) | G37: =IF(D37=0,"Al día",IF(F37<=30,"1-30 días",IF(F37<=60,"31-60 días",IF(F37<=90,"61-90 días","Más de 90 días")))) | H37: =IF(D37=0,"Sin acción",IF(F37<=30,"Recordatorio automático",IF(F37<=60,"Recordatorio escrito personalizado",IF(F37<=90,"Llamar esta semana","Reunión para acuerdo de pago")))) | I37: =D37+ROW()/1000000
A38: Familia 35 | B38: 2 | C38: 900000 | D38: 0 | F38: =IF(D38=0,0,Tablero!$C$3-E38) | G38: =IF(D38=0,"Al día",IF(F38<=30,"1-30 días",IF(F38<=60,"31-60 días",IF(F38<=90,"61-90 días","Más de 90 días")))) | H38: =IF(D38=0,"Sin acción",IF(F38<=30,"Recordatorio automático",IF(F38<=60,"Recordatorio escrito personalizado",IF(F38<=90,"Llamar esta semana","Reunión para acuerdo de pago")))) | I38: =D38+ROW()/1000000
A39: Familia 36 | B39: 1 | C39: 420000 | D39: 0 | F39: =IF(D39=0,0,Tablero!$C$3-E39) | G39: =IF(D39=0,"Al día",IF(F39<=30,"1-30 días",IF(F39<=60,"31-60 días",IF(F39<=90,"61-90 días","Más de 90 días")))) | H39: =IF(D39=0,"Sin acción",IF(F39<=30,"Recordatorio automático",IF(F39<=60,"Recordatorio escrito personalizado",IF(F39<=90,"Llamar esta semana","Reunión para acuerdo de pago")))) | I39: =D39+ROW()/1000000
A40: Familia 37 | B40: 1 | C40: 420000 | D40: 0 | F40: =IF(D40=0,0,Tablero!$C$3-E40) | G40: =IF(D40=0,"Al día",IF(F40<=30,"1-30 días",IF(F40<=60,"31-60 días",IF(F40<=90,"61-90 días","Más de 90 días")))) | H40: =IF(D40=0,"Sin acción",IF(F40<=30,"Recordatorio automático",IF(F40<=60,"Recordatorio escrito personalizado",IF(F40<=90,"Llamar esta semana","Reunión para acuerdo de pago")))) | I40: =D40+ROW()/1000000
A41: Familia 38 | B41: 1 | C41: 420000 | D41: 1260000 | E41: 46223 | F41: =IF(D41=0,0,Tablero!$C$3-E41) | G41: =IF(D41=0,"Al día",IF(F41<=30,"1-30 días",IF(F41<=60,"31-60 días",IF(F41<=90,"61-90 días","Más de 90 días")))) | H41: =IF(D41=0,"Sin acción",IF(F41<=30,"Recordatorio automático",IF(F41<=60,"Recordatorio escrito personalizado",IF(F41<=90,"Llamar esta semana","Reunión para acuerdo de pago")))) | I41: =D41+ROW()/1000000
...
