Workbook

Sheet Rubros
A1: RUBROS Y APROPIACIÓN (ejemplo ficticio de un presupuesto de un colegio; pesos colombianos)
A3: Rubro | B3: Descripción | C3: Apropiación inicial | D3: Adiciones | E3: Reducciones | F3: Apropiación definitiva | G3: CDP expedidos | H3: Comprometido (RP) | I3: Obligado | J3: Pagado | K3: Disponible (apropiación − CDP) | L3: Por comprometer (CDP − RP) | M3: Por obligar (RP − obligado) | N3: Por pagar (obligado − pagado) | O3: % comprometido | P3: % pagado | Q3: Alerta
A4: R1 | B4: Materiales y suministros | C4: 11000000 | D4: 1500000 | E4: 500000 | F4: =IF(A4="","",C4+D4-E4) | G4: =IF(A4="","",SUMIFS(Movimientos!$G$4:$G$300,Movimientos!$A$4:$A$300,"CDP",Movimientos!$E$4:$E$300,A4)) | H4: =IF(A4="","",SUMIFS(Movimientos!$G$4:$G$300,Movimientos!$A$4:$A$300,"RP",Movimientos!$E$4:$E$300,A4)) | I4: =IF(A4="","",SUMIFS(Movimientos!$G$4:$G$300,Movimientos!$A$4:$A$300,"OBL",Movimientos!$E$4:$E$300,A4)) | J4: =IF(A4="","",SUMIFS(Movimientos!$G$4:$G$300,Movimientos!$A$4:$A$300,"PAGO",Movimientos!$E$4:$E$300,A4)) | K4: =IF(A4="","",F4-G4) | L4: =IF(A4="","",G4-H4) | M4: =IF(A4="","",H4-I4) | N4: =IF(A4="","",I4-J4) | O4: =IF(A4="","",IF(F4=0,0,H4/F4)) | P4: =IF(A4="","",IF(F4=0,0,J4/F4)) | Q4: =IF(A4="","",IF(K4<0,"CDP superan la apropiación",IF(COUNTIFS(Movimientos!$E$4:$E$300,A4,Movimientos!$J$4:$J$300,"Excede*")>0,"Hay documentos que exceden el anterior","")))
A5: R2 | B5: Mantenimiento de infraestructura | C5: 18000000 | D5: 0 | E5: 0 | F5: =IF(A5="","",C5+D5-E5) | G5: =IF(A5="","",SUMIFS(Movimientos!$G$4:$G$300,Movimientos!$A$4:$A$300,"CDP",Movimientos!$E$4:$E$300,A5)) | H5: =IF(A5="","",SUMIFS(Movimientos!$G$4:$G$300,Movimientos!$A$4:$A$300,"RP",Movimientos!$E$4:$E$300,A5)) | I5: =IF(A5="","",SUMIFS(Movimientos!$G$4:$G$300,Movimientos!$A$4:$A$300,"OBL",Movimientos!$E$4:$E$300,A5)) | J5: =IF(A5="","",SUMIFS(Movimientos!$G$4:$G$300,Movimientos!$A$4:$A$300,"PAGO",Movimientos!$E$4:$E$300,A5)) | K5: =IF(A5="","",F5-G5) | L5: =IF(A5="","",G5-H5) | M5: =IF(A5="","",H5-I5) | N5: =IF(A5="","",I5-J5) | O5: =IF(A5="","",IF(F5=0,0,H5/F5)) | P5: =IF(A5="","",IF(F5=0,0,J5/F5)) | Q5: =IF(A5="","",IF(K5<0,"CDP superan la apropiación",IF(COUNTIFS(Movimientos!$E$4:$E$300,A5,Movimientos!$J$4:$J$300,"Excede*")>0,"Hay documentos que exceden el anterior","")))
A6: R3 | B6: Servicios públicos | C6: 15000000 | D6: 0 | E6: 0 | F6: =IF(A6="","",C6+D6-E6) | G6: =IF(A6="","",SUMIFS(Movimientos!$G$4:$G$300,Movimientos!$A$4:$A$300,"CDP",Movimientos!$E$4:$E$300,A6)) | H6: =IF(A6="","",SUMIFS(Movimientos!$G$4:$G$300,Movimientos!$A$4:$A$300,"RP",Movimientos!$E$4:$E$300,A6)) | I6: =IF(A6="","",SUMIFS(Movimientos!$G$4:$G$300,Movimientos!$A$4:$A$300,"OBL",Movimientos!$E$4:$E$300,A6)) | J6: =IF(A6="","",SUMIFS(Movimientos!$G$4:$G$300,Movimientos!$A$4:$A$300,"PAGO",Movimientos!$E$4:$E$300,A6)) | K6: =IF(A6="","",F6-G6) | L6: =IF(A6="","",G6-H6) | M6: =IF(A6="","",H6-I6) | N6: =IF(A6="","",I6-J6) | O6: =IF(A6="","",IF(F6=0,0,H6/F6)) | P6: =IF(A6="","",IF(F6=0,0,J6/F6)) | Q6: =IF(A6="","",IF(K6<0,"CDP superan la apropiación",IF(COUNTIFS(Movimientos!$E$4:$E$300,A6,Movimientos!$J$4:$J$300,"Excede*")>0,"Hay documentos que exceden el anterior","")))
A7: R4 | B7: Comunicaciones y transporte | C7: 6000000 | D7: 0 | E7: 0 | F7: =IF(A7="","",C7+D7-E7) | G7: =IF(A7="","",SUMIFS(Movimientos!$G$4:$G$300,Movimientos!$A$4:$A$300,"CDP",Movimientos!$E$4:$E$300,A7)) | H7: =IF(A7="","",SUMIFS(Movimientos!$G$4:$G$300,Movimientos!$A$4:$A$300,"RP",Movimientos!$E$4:$E$300,A7)) | I7: =IF(A7="","",SUMIFS(Movimientos!$G$4:$G$300,Movimientos!$A$4:$A$300,"OBL",Movimientos!$E$4:$E$300,A7)) | J7: =IF(A7="","",SUMIFS(Movimientos!$G$4:$G$300,Movimientos!$A$4:$A$300,"PAGO",Movimientos!$E$4:$E$300,A7)) | K7: =IF(A7="","",F7-G7) | L7: =IF(A7="","",G7-H7) | M7: =IF(A7="","",H7-I7) | N7: =IF(A7="","",I7-J7) | O7: =IF(A7="","",IF(F7=0,0,H7/F7)) | P7: =IF(A7="","",IF(F7=0,0,J7/F7)) | Q7: =IF(A7="","",IF(K7<0,"CDP superan la apropiación",IF(COUNTIFS(Movimientos!$E$4:$E$300,A7,Movimientos!$J$4:$J$300,"Excede*")>0,"Hay documentos que exceden el anterior","")))
A8: R5 | B8: Dotación tecnológica | C8: 20000000 | D8: 5000000 | E8: 0 | F8: =IF(A8="","",C8+D8-E8) | G8: =IF(A8="","",SUMIFS(Movimientos!$G$4:$G$300,Movimientos!$A$4:$A$300,"CDP",Movimientos!$E$4:$E$300,A8)) | H8: =IF(A8="","",SUMIFS(Movimientos!$G$4:$G$300,Movimientos!$A$4:$A$300,"RP",Movimientos!$E$4:$E$300,A8)) | I8: =IF(A8="","",SUMIFS(Movimientos!$G$4:$G$300,Movimientos!$A$4:$A$300,"OBL",Movimientos!$E$4:$E$300,A8)) | J8: =IF(A8="","",SUMIFS(Movimientos!$G$4:$G$300,Movimientos!$A$4:$A$300,"PAGO",Movimientos!$E$4:$E$300,A8)) | K8: =IF(A8="","",F8-G8) | L8: =IF(A8="","",G8-H8) | M8: =IF(A8="","",H8-I8) | N8: =IF(A8="","",I8-J8) | O8: =IF(A8="","",IF(F8=0,0,H8/F8)) | P8: =IF(A8="","",IF(F8=0,0,J8/F8)) | Q8: =IF(A8="","",IF(K8<0,"CDP superan la apropiación",IF(COUNTIFS(Movimientos!$E$4:$E$300,A8,Movimientos!$J$4:$J$300,"Excede*")>0,"Hay documentos que exceden el anterior","")))
A9: R6 | B9: Impresos y publicaciones | C9: 4000000 | D9: 0 | E9: 0 | F9: =IF(A9="","",C9+D9-E9) | G9: =IF(A9="","",SUMIFS(Movimientos!$G$4:$G$300,Movimientos!$A$4:$A$300,"CDP",Movimientos!$E$4:$E$300,A9)) | H9: =IF(A9="","",SUMIFS(Movimientos!$G$4:$G$300,Movimientos!$A$4:$A$300,"RP",Movimientos!$E$4:$E$300,A9)) | I9: =IF(A9="","",SUMIFS(Movimientos!$G$4:$G$300,Movimientos!$A$4:$A$300,"OBL",Movimientos!$E$4:$E$300,A9)) | J9: =IF(A9="","",SUMIFS(Movimientos!$G$4:$G$300,Movimientos!$A$4:$A$300,"PAGO",Movimientos!$E$4:$E$300,A9)) | K9: =IF(A9="","",F9-G9) | L9: =IF(A9="","",G9-H9) | M9: =IF(A9="","",H9-I9) | N9: =IF(A9="","",I9-J9) | O9: =IF(A9="","",IF(F9=0,0,H9/F9)) | P9: =IF(A9="","",IF(F9=0,0,J9/F9)) | Q9: =IF(A9="","",IF(K9<0,"CDP superan la apropiación",IF(COUNTIFS(Movimientos!$E$4:$E$300,A9,Movimientos!$J$4:$J$300,"Excede*")>0,"Hay documentos que exceden el anterior","")))
A10: R7 | B10: Seguros | C10: 5000000 | D10: 0 | E10: 0 | F10: =IF(A10="","",C10+D10-E10) | G10: =IF(A10="","",SUMIFS(Movimientos!$G$4:$G$300,Movimientos!$A$4:$A$300,"CDP",Movimientos!$E$4:$E$300,A10)) | H10: =IF(A10="","",SUMIFS(Movimientos!$G$4:$G$300,Movimientos!$A$4:$A$300,"RP",Movimientos!$E$4:$E$300,A10)) | I10: =IF(A10="","",SUMIFS(Movimientos!$G$4:$G$300,Movimientos!$A$4:$A$300,"OBL",Movimientos!$E$4:$E$300,A10)) | J10: =IF(A10="","",SUMIFS(Movimientos!$G$4:$G$300,Movimientos!$A$4:$A$300,"PAGO",Movimientos!$E$4:$E$300,A10)) | K10: =IF(A10="","",F10-G10) | L10: =IF(A10="","",G10-H10) | M10: =IF(A10="","",H10-I10) | N10: =IF(A10="","",I10-J10) | O10: =IF(A10="","",IF(F10=0,0,H10/F10)) | P10: =IF(A10="","",IF(F10=0,0,J10/F10)) | Q10: =IF(A10="","",IF(K10<0,"CDP superan la apropiación",IF(COUNTIFS(Movimientos!$E$4:$E$300,A10,Movimientos!$J$4:$J$300,"Excede*")>0,"Hay documentos que exceden el anterior","")))
A11: R8 | B11: Capacitación | C11: 3000000 | D11: 0 | E11: 0 | F11: =IF(A11="","",C11+D11-E11) | G11: =IF(A11="","",SUMIFS(Movimientos!$G$4:$G$300,Movimientos!$A$4:$A$300,"CDP",Movimientos!$E$4:$E$300,A11)) | H11: =IF(A11="","",SUMIFS(Movimientos!$G$4:$G$300,Movimientos!$A$4:$A$300,"RP",Movimientos!$E$4:$E$300,A11)) | I11: =IF(A11="","",SUMIFS(Movimientos!$G$4:$G$300,Movimientos!$A$4:$A$300,"OBL",Movimientos!$E$4:$E$300,A11)) | J11: =IF(A11="","",SUMIFS(Movimientos!$G$4:$G$300,Movimientos!$A$4:$A$300,"PAGO",Movimientos!$E$4:$E$300,A11)) | K11: =IF(A11="","",F11-G11) | L11: =IF(A11="","",G11-H11) | M11: =IF(A11="","",H11-I11) | N11: =IF(A11="","",I11-J11) | O11: =IF(A11="","",IF(F11=0,0,H11/F11)) | P11: =IF(A11="","",IF(F11=0,0,J11/F11)) | Q11: =IF(A11="","",IF(K11<0,"CDP superan la apropiación",IF(COUNTIFS(Movimientos!$E$4:$E$300,A11,Movimientos!$J$4:$J$300,"Excede*")>0,"Hay documentos que exceden el anterior","")))
F12: =IF(A12="","",C12+D12-E12) | G12: =IF(A12="","",SUMIFS(Movimientos!$G$4:$G$300,Movimientos!$A$4:$A$300,"CDP",Movimientos!$E$4:$E$300,A12)) | H12: =IF(A12="","",SUMIFS(Movimientos!$G$4:$G$300,Movimientos!$A$4:$A$300,"RP",Movimientos!$E$4:$E$300,A12)) | I12: =IF(A12="","",SUMIFS(Movimientos!$G$4:$G$300,Movimientos!$A$4:$A$300,"OBL",Movimientos!$E$4:$E$300,A12)) | J12: =IF(A12="","",SUMIFS(Movimientos!$G$4:$G$300,Movimientos!$A$4:$A$300,"PAGO",Movimientos!$E$4:$E$300,A12)) | K12: =IF(A12="","",F12-G12) | L12: =IF(A12="","",G12-H12) | M12: =IF(A12="","",H12-I12) | N12: =IF(A12="","",I12-J12) | O12: =IF(A12="","",IF(F12=0,0,H12/F12)) | P12: =IF(A12="","",IF(F12=0,0,J12/F12)) | Q12: =IF(A12="","",IF(K12<0,"CDP superan la apropiación",IF(COUNTIFS(Movimientos!$E$4:$E$300,A12,Movimientos!$J$4:$J$300,"Excede*")>0,"Hay documentos que exceden el anterior","")))
F13: =IF(A13="","",C13+D13-E13) | G13: =IF(A13="","",SUMIFS(Movimientos!$G$4:$G$300,Movimientos!$A$4:$A$300,"CDP",Movimientos!$E$4:$E$300,A13)) | H13: =IF(A13="","",SUMIFS(Movimientos!$G$4:$G$300,Movimientos!$A$4:$A$300,"RP",Movimientos!$E$4:$E$300,A13)) | I13: =IF(A13="","",SUMIFS(Movimientos!$G$4:$G$300,Movimientos!$A$4:$A$300,"OBL",Movimientos!$E$4:$E$300,A13)) | J13: =IF(A13="","",SUMIFS(Movimientos!$G$4:$G$300,Movimientos!$A$4:$A$300,"PAGO",Movimientos!$E$4:$E$300,A13)) | K13: =IF(A13="","",F13-G13) | L13: =IF(A13="","",G13-H13) | M13: =IF(A13="","",H13-I13) | N13: =IF(A13="","",I13-J13) | O13: =IF(A13="","",IF(F13=0,0,H13/F13)) | P13: =IF(A13="","",IF(F13=0,0,J13/F13)) | Q13: =IF(A13="","",IF(K13<0,"CDP superan la apropiación",IF(COUNTIFS(Movimientos!$E$4:$E$300,A13,Movimientos!$J$4:$J$300,"Excede*")>0,"Hay documentos que exceden el anterior","")))
F14: =IF(A14="","",C14+D14-E14) | G14: =IF(A14="","",SUMIFS(Movimientos!$G$4:$G$300,Movimientos!$A$4:$A$300,"CDP",Movimientos!$E$4:$E$300,A14)) | H14: =IF(A14="","",SUMIFS(Movimientos!$G$4:$G$300,Movimientos!$A$4:$A$300,"RP",Movimientos!$E$4:$E$300,A14)) | I14: =IF(A14="","",SUMIFS(Movimientos!$G$4:$G$300,Movimientos!$A$4:$A$300,"OBL",Movimientos!$E$4:$E$300,A14)) | J14: =IF(A14="","",SUMIFS(Movimientos!$G$4:$G$300,Movimientos!$A$4:$A$300,"PAGO",Movimientos!$E$4:$E$300,A14)) | K14: =IF(A14="","",F14-G14) | L14: =IF(A14="","",G14-H14) | M14: =IF(A14="","",H14-I14) | N14: =IF(A14="","",I14-J14) | O14: =IF(A14="","",IF(F14=0,0,H14/F14)) | P14: =IF(A14="","",IF(F14=0,0,J14/F14)) | Q14: =IF(A14="","",IF(K14<0,"CDP superan la apropiación",IF(COUNTIFS(Movimientos!$E$4:$E$300,A14,Movimientos!$J$4:$J$300,"Excede*")>0,"Hay documentos que exceden el anterior","")))
F15: =IF(A15="","",C15+D15-E15) | G15: =IF(A15="","",SUMIFS(Movimientos!$G$4:$G$300,Movimientos!$A$4:$A$300,"CDP",Movimientos!$E$4:$E$300,A15)) | H15: =IF(A15="","",SUMIFS(Movimientos!$G$4:$G$300,Movimientos!$A$4:$A$300,"RP",Movimientos!$E$4:$E$300,A15)) | I15: =IF(A15="","",SUMIFS(Movimientos!$G$4:$G$300,Movimientos!$A$4:$A$300,"OBL",Movimientos!$E$4:$E$300,A15)) | J15: =IF(A15="","",SUMIFS(Movimientos!$G$4:$G$300,Movimientos!$A$4:$A$300,"PAGO",Movimientos!$E$4:$E$300,A15)) | K15: =IF(A15="","",F15-G15) | L15: =IF(A15="","",G15-H15) | M15: =IF(A15="","",H15-I15) | N15: =IF(A15="","",I15-J15) | O15: =IF(A15="","",IF(F15=0,0,H15/F15)) | P15: =IF(A15="","",IF(F15=0,0,J15/F15)) | Q15: =IF(A15="","",IF(K15<0,"CDP superan la apropiación",IF(COUNTIFS(Movimientos!$E$4:$E$300,A15,Movimientos!$J$4:$J$300,"Excede*")>0,"Hay documentos que exceden el anterior","")))
F16: =IF(A16="","",C16+D16-E16) | G16: =IF(A16="","",SUMIFS(Movimientos!$G$4:$G$300,Movimientos!$A$4:$A$300,"CDP",Movimientos!$E$4:$E$300,A16)) | H16: =IF(A16="","",SUMIFS(Movimientos!$G$4:$G$300,Movimientos!$A$4:$A$300,"RP",Movimientos!$E$4:$E$300,A16)) | I16: =IF(A16="","",SUMIFS(Movimientos!$G$4:$G$300,Movimientos!$A$4:$A$300,"OBL",Movimientos!$E$4:$E$300,A16)) | J16: =IF(A16="","",SUMIFS(Movimientos!$G$4:$G$300,Movimientos!$A$4:$A$300,"PAGO",Movimientos!$E$4:$E$300,A16)) | K16: =IF(A16="","",F16-G16) | L16: =IF(A16="","",G16-H16) | M16: =IF(A16="","",H16-I16) | N16: =IF(A16="","",I16-J16) | O16: =IF(A16="","",IF(F16=0,0,H16/F16)) | P16: =IF(A16="","",IF(F16=0,0,J16/F16)) | Q16: =IF(A16="","",IF(K16<0,"CDP superan la apropiación",IF(COUNTIFS(Movimientos!$E$4:$E$300,A16,Movimientos!$J$4:$J$300,"Excede*")>0,"Hay documentos que exceden el anterior","")))
F17: =IF(A17="","",C17+D17-E17) | G17: =IF(A17="","",SUMIFS(Movimientos!$G$4:$G$300,Movimientos!$A$4:$A$300,"CDP",Movimientos!$E$4:$E$300,A17)) | H17: =IF(A17="","",SUMIFS(Movimientos!$G$4:$G$300,Movimientos!$A$4:$A$300,"RP",Movimientos!$E$4:$E$300,A17)) | I17: =IF(A17="","",SUMIFS(Movimientos!$G$4:$G$300,Movimientos!$A$4:$A$300,"OBL",Movimientos!$E$4:$E$300,A17)) | J17: =IF(A17="","",SUMIFS(Movimientos!$G$4:$G$300,Movimientos!$A$4:$A$300,"PAGO",Movimientos!$E$4:$E$300,A17)) | K17: =IF(A17="","",F17-G17) | L17: =IF(A17="","",G17-H17) | M17: =IF(A17="","",H17-I17) | N17: =IF(A17="","",I17-J17) | O17: =IF(A17="","",IF(F17=0,0,H17/F17)) | P17: =IF(A17="","",IF(F17=0,0,J17/F17)) | Q17: =IF(A17="","",IF(K17<0,"CDP superan la apropiación",IF(COUNTIFS(Movimientos!$E$4:$E$300,A17,Movimientos!$J$4:$J$300,"Excede*")>0,"Hay documentos que exceden el anterior","")))
F18: =IF(A18="","",C18+D18-E18) | G18: =IF(A18="","",SUMIFS(Movimientos!$G$4:$G$300,Movimientos!$A$4:$A$300,"CDP",Movimientos!$E$4:$E$300,A18)) | H18: =IF(A18="","",SUMIFS(Movimientos!$G$4:$G$300,Movimientos!$A$4:$A$300,"RP",Movimientos!$E$4:$E$300,A18)) | I18: =IF(A18="","",SUMIFS(Movimientos!$G$4:$G$300,Movimientos!$A$4:$A$300,"OBL",Movimientos!$E$4:$E$300,A18)) | J18: =IF(A18="","",SUMIFS(Movimientos!$G$4:$G$300,Movimientos!$A$4:$A$300,"PAGO",Movimientos!$E$4:$E$300,A18)) | K18: =IF(A18="","",F18-G18) | L18: =IF(A18="","",G18-H18) | M18: =IF(A18="","",H18-I18) | N18: =IF(A18="","",I18-J18) | O18: =IF(A18="","",IF(F18=0,0,H18/F18)) | P18: =IF(A18="","",IF(F18=0,0,J18/F18)) | Q18: =IF(A18="","",IF(K18<0,"CDP superan la apropiación",IF(COUNTIFS(Movimientos!$E$4:$E$300,A18,Movimientos!$J$4:$J$300,"Excede*")>0,"Hay documentos que exceden el anterior","")))
A20: TOTAL | C20: =SUM(C4:C18) | D20: =SUM(D4:D18) | E20: =SUM(E4:E18) | F20: =SUM(F4:F18) | G20: =SUM(G4:G18) | H20: =SUM(H4:H18) | I20: =SUM(I4:I18) | J20: =SUM(J4:J18) | ... N20: =SUM(N4:N18) | O20: =IF(F20=0,0,H20/F20) | P20: =IF(F20=0,0,J20/F20)

Sheet Resumen
A1: RESUMEN DE EJECUCIÓN
A3: Apropiación definitiva | B3: =Rubros!F20
A4: CDP expedidos | B4: =Rubros!G20
A5: Comprometido (RP) | B5: =Rubros!H20
A6: Obligado | B6: =Rubros!I20
A7: Pagado | B7: =Rubros!J20
A8: Disponible para nuevos CDP | B8: =Rubros!K20
A9: Por comprometer (CDP sin RP) | B9: =Rubros!L20
A10: Por pagar (obligado sin pagar) | B10: =Rubros!N20
A11: % comprometido | B11: =Rubros!O20
A12: % pagado | B12: =Rubros!P20
A13: Rubros con CDP que superan la apropiación | B13: =COUNTIF(Rubros!K4:K18,"<0")
A14: Documentos que exceden el anterior | B14: =COUNTIF(Movimientos!J4:J300,"Excede*")
A15: Documentos sin documento previo | B15: =COUNTIF(Movimientos!J4:J300,"Falta*")
A17: Ciclo del gasto (resumen): apropiación → CDP (reserva disponibilidad) → RP (compromiso) → obligación (recibido el bien o servicio) → pago.

Sheet Movimientos
A1: MOVIMIENTOS PRESUPUESTALES (cada documento con su referencia al documento previo: RP → CDP, obligación → RP, pago → obligación)
A3: Tipo | B3: Número | C3: Documento previo | D3: Descripción | E3: Rubro | F3: Fecha | G3: Valor | H3: Suma de documentos que lo referencian | I3: Saldo del documento | J3: Control
A4: CDP | B4: CDP-001 | E4: R1 | F4: 46419 | G4: 5000000 | H4: =IF(B4="","",SUMIFS($G$4:$G$300,$C$4:$C$300,B4)) | I4: =IF(OR(B4="",A4="PAGO"),"",G4-H4) | J4: =IF(B4="","",IF(AND(A4<>"PAGO",H4>G4),"Excede el documento (los posteriores suman más)",IF(AND(A4<>"CDP",C4=""),"Falta el documento previo","OK")))
A5: RP | B5: RP-001 | C5: CDP-001 | E5: R1 | F5: 46421 | G5: 4800000 | H5: =IF(B5="","",SUMIFS($G$4:$G$300,$C$4:$C$300,B5)) | I5: =IF(OR(B5="",A5="PAGO"),"",G5-H5) | J5: =IF(B5="","",IF(AND(A5<>"PAGO",H5>G5),"Excede el documento (los posteriores suman más)",IF(AND(A5<>"CDP",C5=""),"Falta el documento previo","OK")))
A6: OBL | B6: OB-001 | C6: RP-001 | E6: R1 | F6: 46428 | G6: 4800000 | H6: =IF(B6="","",SUMIFS($G$4:$G$300,$C$4:$C$300,B6)) | I6: =IF(OR(B6="",A6="PAGO"),"",G6-H6) | J6: =IF(B6="","",IF(AND(A6<>"PAGO",H6>G6),"Excede el documento (los posteriores suman más)",IF(AND(A6<>"CDP",C6=""),"Falta el documento previo","OK")))
A7: PAGO | B7: PG-001 | C7: OB-001 | E7: R1 | F7: 46430 | G7: 4800000 | H7: =IF(B7="","",SUMIFS($G$4:$G$300,$C$4:$C$300,B7)) | I7: =IF(OR(B7="",A7="PAGO"),"",G7-H7) | J7: =IF(B7="","",IF(AND(A7<>"PAGO",H7>G7),"Excede el documento (los posteriores suman más)",IF(AND(A7<>"CDP",C7=""),"Falta el documento previo","OK")))
A8: CDP | B8: CDP-002 | E8: R2 | F8: 46420 | G8: 12000000 | H8: =IF(B8="","",SUMIFS($G$4:$G$300,$C$4:$C$300,B8)) | I8: =IF(OR(B8="",A8="PAGO"),"",G8-H8) | J8: =IF(B8="","",IF(AND(A8<>"PAGO",H8>G8),"Excede el documento (los posteriores suman más)",IF(AND(A8<>"CDP",C8=""),"Falta el documento previo","OK")))
A9: RP | B9: RP-002 | C9: CDP-002 | E9: R2 | F9: 46423 | G9: 11500000 | H9: =IF(B9="","",SUMIFS($G$4:$G$300,$C$4:$C$300,B9)) | I9: =IF(OR(B9="",A9="PAGO"),"",G9-H9) | J9: =IF(B9="","",IF(AND(A9<>"PAGO",H9>G9),"Excede el documento (los posteriores suman más)",IF(AND(A9<>"CDP",C9=""),"Falta el documento previo","OK")))
A10: OBL | B10: OB-002 | C10: RP-002 | E10: R2 | F10: 46438 | G10: 6000000 | H10: =IF(B10="","",SUMIFS($G$4:$G$300,$C$4:$C$300,B10)) | I10: =IF(OR(B10="",A10="PAGO"),"",G10-H10) | J10: =IF(B10="","",IF(AND(A10<>"PAGO",H10>G10),"Excede el documento (los posteriores suman más)",IF(AND(A10<>"CDP",C10=""),"Falta el documento previo","OK")))
A11: PAGO | B11: PG-002 | C11: OB-002 | E11: R2 | F11: 46442 | G11: 6000000 | H11: =IF(B11="","",SUMIFS($G$4:$G$300,$C$4:$C$300,B11)) | I11: =IF(OR(B11="",A11="PAGO"),"",G11-H11) | J11: =IF(B11="","",IF(AND(A11<>"PAGO",H11>G11),"Excede el documento (los posteriores suman más)",IF(AND(A11<>"CDP",C11=""),"Falta el documento previo","OK")))
A12: CDP | B12: CDP-003 | E12: R3 | F12: 46420 | G12: 9000000 | H12: =IF(B12="","",SUMIFS($G$4:$G$300,$C$4:$C$300,B12)) | I12: =IF(OR(B12="",A12="PAGO"),"",G12-H12) | J12: =IF(B12="","",IF(AND(A12<>"PAGO",H12>G12),"Excede el documento (los posteriores suman más)",IF(AND(A12<>"CDP",C12=""),"Falta el documento previo","OK")))
A13: RP | B13: RP-003 | C13: CDP-003 | E13: R3 | F13: 46422 | G13: 9000000 | H13: =IF(B13="","",SUMIFS($G$4:$G$300,$C$4:$C$300,B13)) | I13: =IF(OR(B13="",A13="PAGO"),"",G13-H13) | J13: =IF(B13="","",IF(AND(A13<>"PAGO",H13>G13),"Excede el documento (los posteriores suman más)",IF(AND(A13<>"CDP",C13=""),"Falta el documento previo","OK")))
A14: OBL | B14: OB-003 | C14: RP-003 | E14: R3 | F14: 46446 | G14: 4500000 | H14: =IF(B14="","",SUMIFS($G$4:$G$300,$C$4:$C$300,B14)) | I14: =IF(OR(B14="",A14="PAGO"),"",G14-H14) | J14: =IF(B14="","",IF(AND(A14<>"PAGO",H14>G14),"Excede el documento (los posteriores suman más)",IF(AND(A14<>"CDP",C14=""),"Falta el documento previo","OK")))
A15: PAGO | B15: PG-003 | C15: OB-003 | E15: R3 | F15: 46448 | G15: 4500000 | H15: =IF(B15="","",SUMIFS($G$4:$G$300,$C$4:$C$300,B15)) | I15: =IF(OR(B15="",A15="PAGO"),"",G15-H15) | J15: =IF(B15="","",IF(AND(A15<>"PAGO",H15>G15),"Excede el documento (los posteriores suman más)",IF(AND(A15<>"CDP",C15=""),"Falta el documento previo","OK")))
A16: CDP | B16: CDP-004 | E16: R5 | F16: 46426 | G16: 20000000 | H16: =IF(B16="","",SUMIFS($G$4:$G$300,$C$4:$C$300,B16)) | I16: =IF(OR(B16="",A16="PAGO"),"",G16-H16) | J16: =IF(B16="","",IF(AND(A16<>"PAGO",H16>G16),"Excede el documento (los posteriores suman más)",IF(AND(A16<>"CDP",C16=""),"Falta el documento previo","OK")))
A17: RP | B17: RP-004 | C17: CDP-004 | E17: R5 | F17: 46427 | G17: 20000000 | H17: =IF(B17="","",SUMIFS($G$4:$G$300,$C$4:$C$300,B17)) | I17: =IF(OR(B17="",A17="PAGO"),"",G17-H17) | J17: =IF(B17="","",IF(AND(A17<>"PAGO",H17>G17),"Excede el documento (los posteriores suman más)",IF(AND(A17<>"CDP",C17=""),"Falta el documento previo","OK")))
A18: OBL | B18: OB-004 | C18: RP-004 | E18: R5 | F18: 46447 | G18: 15000000 | H18: =IF(B18="","",SUMIFS($G$4:$G$300,$C$4:$C$300,B18)) | I18: =IF(OR(B18="",A18="PAGO"),"",G18-H18) | J18: =IF(B18="","",IF(AND(A18<>"PAGO",H18>G18),"Excede el documento (los posteriores suman más)",IF(AND(A18<>"CDP",C18=""),"Falta el documento previo","OK")))
A19: PAGO | B19: PG-004 | C19: OB-004 | E19: R5 | F19: 46451 | G19: 10000000 | H19: =IF(B19="","",SUMIFS($G$4:$G$300,$C$4:$C$300,B19)) | I19: =IF(OR(B19="",A19="PAGO"),"",G19-H19) | J19: =IF(B19="","",IF(AND(A19<>"PAGO",H19>G19),"Excede el documento (los posteriores suman más)",IF(AND(A19<>"CDP",C19=""),"Falta el documento previo","OK")))
A20: CDP | B20: CDP-005 | E20: R4 | F20: 46427 | G20: 2000000 | H20: =IF(B20="","",SUMIFS($G$4:$G$300,$C$4:$C$300,B20)) | I20: =IF(OR(B20="",A20="PAGO"),"",G20-H20) | J20: =IF(B20="","",IF(AND(A20<>"PAGO",H20>G20),"Excede el documento (los posteriores suman más)",IF(AND(A20<>"CDP",C20=""),"Falta el documento previo","OK")))
A21: RP | B21: RP-005 | C21: CDP-005 | E21: R4 | F21: 46429 | G21: 2300000 | H21: =IF(B21="","",SUMIFS($G$4:$G$300,$C$4:$C$300,B21)) | I21: =IF(OR(B21="",A21="PAGO"),"",G21-H21) | J21: =IF(B21="","",IF(AND(A21<>"PAGO",H21>G21),"Excede el documento (los posteriores suman más)",IF(AND(A21<>"CDP",C21=""),"Falta el documento previo","OK")))
A22: OBL | B22: OB-005 | C22: RP-005 | E22: R4 | F22: 46443 | G22: 2300000 | H22: =IF(B22="","",SUMIFS($G$4:$G$300,$C$4:$C$300,B22)) | I22: =IF(OR(B22="",A22="PAGO"),"",G22-H22) | J22: =IF(B22="","",IF(AND(A22<>"PAGO",H22>G22),"Excede el documento (los posteriores suman más)",IF(AND(A22<>"CDP",C22=""),"Falta el documento previo","OK")))
A23: PAGO | B23: PG-005 | C23: OB-005 | E23: R4 | F23: 46444 | G23: 2300000 | H23: =IF(B23="","",SUMIFS($G$4:$G$300,$C$4:$C$300,B23)) | I23: =IF(OR(B23="",A23="PAGO"),"",G23-H23) | J23: =IF(B23="","",IF(AND(A23<>"PAGO",H23>G23),"Excede el documento (los posteriores suman más)",IF(AND(A23<>"CDP",C23=""),"Falta el documento previo","OK")))
A24: CDP | B24: CDP-006 | E24: R6 | F24: 46433 | G24: 3000000 | H24: =IF(B24="","",SUMIFS($G$4:$G$300,$C$4:$C$300,B24)) | I24: =IF(OR(B24="",A24="PAGO"),"",G24-H24) | J24: =IF(B24="","",IF(AND(A24<>"PAGO",H24>G24),"Excede el documento (los posteriores suman más)",IF(AND(A24<>"CDP",C24=""),"Falta el documento previo","OK")))
A25: CDP | B25: CDP-007 | E25: R7 | F25: 46434 | G25: 5000000 | H25: =IF(B25="","",SUMIFS($G$4:$G$300,$C$4:$C$300,B25)) | I25: =IF(OR(B25="",A25="PAGO"),"",G25-H25) | J25: =IF(B25="","",IF(AND(A25<>"PAGO",H25>G25),"Excede el documento (los posteriores suman más)",IF(AND(A25<>"CDP",C25=""),"Falta el documento previo","OK")))
A26: RP | B26: RP-006 | C26: CDP-007 | E26: R7 | F26: 46435 | G26: 5000000 | H26: =IF(B26="","",SUMIFS($G$4:$G$300,$C$4:$C$300,B26)) | I26: =IF(OR(B26="",A26="PAGO"),"",G26-H26) | J26: =IF(B26="","",IF(AND(A26<>"PAGO",H26>G26),"Excede el documento (los posteriores suman más)",IF(AND(A26<>"CDP",C26=""),"Falta el documento previo","OK")))
A27: OBL | B27: OB-006 | C27: RP-006 | E27: R7 | F27: 46445 | G27: 5000000 | H27: =IF(B27="","",SUMIFS($G$4:$G$300,$C$4:$C$300,B27)) | I27: =IF(OR(B27="",A27="PAGO"),"",G27-H27) | J27: =IF(B27="","",IF(AND(A27<>"PAGO",H27>G27),"Excede el documento (los posteriores suman más)",IF(AND(A27<>"CDP",C27=""),"Falta el documento previo","OK")))
A28: PAGO | B28: PG-006 | C28: OB-006 | E28: R7 | F28: 46449 | G28: 4000000 | H28: =IF(B28="","",SUMIFS($G$4:$G$300,$C$4:$C$300,B28)) | I28: =IF(OR(B28="",A28="PAGO"),"",G28-H28) | J28: =IF(B28="","",IF(AND(A28<>"PAGO",H28>G28),"Excede el documento (los posteriores suman más)",IF(AND(A28<>"CDP",C28=""),"Falta el documento previo","OK")))
A29: CDP | B29: CDP-008 | E29: R1 | F29: 46436 | G29: 6000000 | H29: =IF(B29="","",SUMIFS($G$4:$G$300,$C$4:$C$300,B29)) | I29: =IF(OR(B29="",A29="PAGO"),"",G29-H29) | J29: =IF(B29="","",IF(AND(A29<>"PAGO",H29>G29),"Excede el documento (los posteriores suman más)",IF(AND(A29<>"CDP",C29=""),"Falta el documento previo","OK")))
A30: RP | B30: RP-007 | C30: CDP-008 | E30: R1 | F30: 46437 | G30: 6000000 | H30: =IF(B30="","",SUMIFS($G$4:$G$300,$C$4:$C$300,B30)) | I30: =IF(OR(B30="",A30="PAGO"),"",G30-H30) | J30: =IF(B30="","",IF(AND(A30<>"PAGO",H30>G30),"Excede el documento (los posteriores suman más)",IF(AND(A30<>"CDP",C30=""),"Falta el documento previo","OK")))
A31: OBL | B31: OB-007 | C31: RP-007 | E31: R1 | F31: 46444 | G31: 6000000 | H31: =IF(B31="","",SUMIFS($G$4:$G$300,$C$4:$C$300,B31)) | I31: =IF(OR(B31="",A31="PAGO"),"",G31-H31) | J31: =IF(B31="","",IF(AND(A31<>"PAGO",H31>G31),"Excede el documento (los posteriores suman más)",IF(AND(A31<>"CDP",C31=""),"Falta el documento previo","OK")))
A32: PAGO | B32: PG-007 | C32: OB-007 | E32: R1 | F32: 46447 | G32: 6000000 | H32: =IF(B32="","",SUMIFS($G$4:$G$300,$C$4:$C$300,B32)) | I32: =IF(OR(B32="",A32="PAGO"),"",G32-H32) | J32: =IF(B32="","",IF(AND(A32<>"PAGO",H32>G32),"Excede el documento (los posteriores suman más)",IF(AND(A32<>"CDP",C32=""),"Falta el documento previo","OK")))
A33: CDP | B33: CDP-009 | E33: R8 | F33: 46440 | G33: 3500000 | H33: =IF(B33="","",SUMIFS($G$4:$G$300,$C$4:$C$300,B33)) | I33: =IF(OR(B33="",A33="PAGO"),"",G33-H33) | J33: =IF(B33="","",IF(AND(A33<>"PAGO",H33>G33),"Excede el documento (los posteriores suman más)",IF(AND(A33<>"CDP",C33=""),"Falta el documento previo","OK")))
H34: =IF(B34="","",SUMIFS($G$4:$G$300,$C$4:$C$300,B34)) | I34: =IF(OR(B34="",A34="PAGO"),"",G34-H34) | J34: =IF(B34="","",IF(AND(A34<>"PAGO",H34>G34),"Excede el documento (los posteriores suman más)",IF(AND(A34<>"CDP",C34=""),"Falta el documento previo","OK")))
H35: =IF(B35="","",SUMIFS($G$4:$G$300,$C$4:$C$300,B35)) | I35: =IF(OR(B35="",A35="PAGO"),"",G35-H35) | J35: =IF(B35="","",IF(AND(A35<>"PAGO",H35>G35),"Excede el documento (los posteriores suman más)",IF(AND(A35<>"CDP",C35=""),"Falta el documento previo","OK")))
H36: =IF(B36="","",SUMIFS($G$4:$G$300,$C$4:$C$300,B36)) | I36: =IF(OR(B36="",A36="PAGO"),"",G36-H36) | J36: =IF(B36="","",IF(AND(A36<>"PAGO",H36>G36),"Excede el documento (los posteriores suman más)",IF(AND(A36<>"CDP",C36=""),"Falta el documento previo","OK")))
H37: =IF(B37="","",SUMIFS($G$4:$G$300,$C$4:$C$300,B37)) | I37: =IF(OR(B37="",A37="PAGO"),"",G37-H37) | J37: =IF(B37="","",IF(AND(A37<>"PAGO",H37>G37),"Excede el documento (los posteriores suman más)",IF(AND(A37<>"CDP",C37=""),"Falta el documento previo","OK")))
H38: =IF(B38="","",SUMIFS($G$4:$G$300,$C$4:$C$300,B38)) | I38: =IF(OR(B38="",A38="PAGO"),"",G38-H38) | J38: =IF(B38="","",IF(AND(A38<>"PAGO",H38>G38),"Excede el documento (los posteriores suman más)",IF(AND(A38<>"CDP",C38=""),"Falta el documento previo","OK")))
H39: =IF(B39="","",SUMIFS($G$4:$G$300,$C$4:$C$300,B39)) | I39: =IF(OR(B39="",A39="PAGO"),"",G39-H39) | J39: =IF(B39="","",IF(AND(A39<>"PAGO",H39>G39),"Excede el documento (los posteriores suman más)",IF(AND(A39<>"CDP",C39=""),"Falta el documento previo","OK")))
H40: =IF(B40="","",SUMIFS($G$4:$G$300,$C$4:$C$300,B40)) | I40: =IF(OR(B40="",A40="PAGO"),"",G40-H40) | J40: =IF(B40="","",IF(AND(A40<>"PAGO",H40>G40),"Excede el documento (los posteriores suman más)",IF(AND(A40<>"CDP",C40=""),"Falta el documento previo","OK")))
H41: =IF(B41="","",SUMIFS($G$4:$G$300,$C$4:$C$300,B41)) | I41: =IF(OR(B41="",A41="PAGO"),"",G41-H41) | J41: =IF(B41="","",IF(AND(A41<>"PAGO",H41>G41),"Excede el documento (los posteriores suman más)",IF(AND(A41<>"CDP",C41=""),"Falta el documento previo","OK")))
...
