Workbook

Sheet Comparador
A1: COMPARADOR DE DOS OFERTAS DE CRÉDITO (ejemplo con datos ficticios; en pesos colombianos)
A2: Completa las celdas amarillas con lo que dice cada oferta. Usa la tasa efectiva anual (E. A.), no la nominal.
A4: Concepto | B4: Oferta A | C4: Oferta B | D4: Diferencia (B − A)
A5: Monto del crédito | B5: 20000000 | C5: 20000000
A6: Plazo (meses) | B6: 36 | C6: 36
A7: Tasa efectiva anual (E. A.) | B7: 0.2 | C7: 0.225
A8: Seguro y otros cobros mensuales fijos | B8: 45000 | C8: 12000
A9: Comisión o costos al inicio (descontados del desembolso) | B9: 400000 | C9: 0
A11: RESULTADOS
A12: Tasa mensual equivalente | B12: =(1+B7)^(1/12)-1 | C12: =(1+C7)^(1/12)-1
A13: Cuota del crédito (capital e intereses) | B13: =PMT(B12,B6,-B5) | C13: =PMT(C12,C6,-C5)
A14: Cuota mensual total (con seguro y otros) | B14: =B13+B8 | C14: =C13+C8 | D14: =C14-B14
A15: Desembolso neto (lo que recibes) | B15: =B5-B9 | C15: =C5-C9
A16: Total que pagarás | B16: =B14*B6+B9 | C16: =C14*C6+C9 | D16: =C16-B16
A17: Costo total del crédito (total − monto) | B17: =B16-B5 | C17: =C16-C5 | D17: =C17-B17
A18: Tasa mensual real (incluye seguro y comisión) | B18: =RATE(B6,-B14,B15) | C18: =RATE(C6,-C14,C15)
A19: Tasa efectiva anual REAL | B19: =(1+B18)^12-1 | C19: =(1+C18)^12-1 | D19: =C19-B19
A21: La oferta más barata por costo total es | B21: =IF(B16<C16,"Oferta A",IF(C16<B16,"Oferta B","Empate"))
A22: La de menor tasa anunciada (E. A.) es | B22: =IF(B7<C7,"Oferta A",IF(C7<B7,"Oferta B","Empate"))
A23: Ahorro de la más barata frente a la otra | B23: =ABS(B16-C16)
A25: TOPE DE USURA (referencia): escribe el interés bancario corriente (IBC) que certifica la Superfinanciera para tu modalidad
A26: IBC vigente (E. A.) — ejemplo; reemplázalo con la certificación del mes | B26: 0.1624
A27: Tope máximo (1,5 × IBC) | B27: =1.5*B26 | C27: =B27
A28: Tasa E. A. anunciada de la oferta A / B frente al tope | B28: =IF(B7>B27,"Supera el tope","Dentro del tope") | C28: =IF(C7>C27,"Supera el tope","Dentro del tope")
A30: Nota: el tope de usura aplica al interés pactado; los seguros y comisiones tienen su propia regulación. La tasa real de esta hoja mezcla todo para comparar, no para determinar si hay usura: ante una duda, consulta a la entidad o a la Superintendencia Financiera.

Sheet Amortizacion_A
A1: TABLA DE AMORTIZACIÓN DE LA OFERTA A (hasta 60 cuotas; se llena según el plazo)
A3: Cuota | B3: Saldo inicial | C3: Interés | D3: Abono a capital | E3: Cuota del crédito | F3: Saldo final | H3: Intereses totales | I3: =SUM(C4:C63)
A4: =IF(1<=Comparador!$B$6,1,"") | B4: =IF(A4="","",Comparador!$B$5) | C4: =IF(A4="","",B4*Comparador!$B$12) | D4: =IF(A4="","",E4-C4) | E4: =IF(A4="","",Comparador!$B$13) | F4: =IF(A4="","",B4-D4) | H4: Capital pagado | I4: =SUM(D4:D63)
A5: =IF(2<=Comparador!$B$6,2,"") | B5: =IF(A5="","",F4) | C5: =IF(A5="","",B5*Comparador!$B$12) | D5: =IF(A5="","",E5-C5) | E5: =IF(A5="","",Comparador!$B$13) | F5: =IF(A5="","",B5-D5) | H5: Saldo final | I5: =INDEX(F4:F63,Comparador!B6)
A6: =IF(3<=Comparador!$B$6,3,"") | B6: =IF(A6="","",F5) | C6: =IF(A6="","",B6*Comparador!$B$12) | D6: =IF(A6="","",E6-C6) | E6: =IF(A6="","",Comparador!$B$13) | F6: =IF(A6="","",B6-D6)
A7: =IF(4<=Comparador!$B$6,4,"") | B7: =IF(A7="","",F6) | C7: =IF(A7="","",B7*Comparador!$B$12) | D7: =IF(A7="","",E7-C7) | E7: =IF(A7="","",Comparador!$B$13) | F7: =IF(A7="","",B7-D7)
A8: =IF(5<=Comparador!$B$6,5,"") | B8: =IF(A8="","",F7) | C8: =IF(A8="","",B8*Comparador!$B$12) | D8: =IF(A8="","",E8-C8) | E8: =IF(A8="","",Comparador!$B$13) | F8: =IF(A8="","",B8-D8)
A9: =IF(6<=Comparador!$B$6,6,"") | B9: =IF(A9="","",F8) | C9: =IF(A9="","",B9*Comparador!$B$12) | D9: =IF(A9="","",E9-C9) | E9: =IF(A9="","",Comparador!$B$13) | F9: =IF(A9="","",B9-D9)
A10: =IF(7<=Comparador!$B$6,7,"") | B10: =IF(A10="","",F9) | C10: =IF(A10="","",B10*Comparador!$B$12) | D10: =IF(A10="","",E10-C10) | E10: =IF(A10="","",Comparador!$B$13) | F10: =IF(A10="","",B10-D10)
A11: =IF(8<=Comparador!$B$6,8,"") | B11: =IF(A11="","",F10) | C11: =IF(A11="","",B11*Comparador!$B$12) | D11: =IF(A11="","",E11-C11) | E11: =IF(A11="","",Comparador!$B$13) | F11: =IF(A11="","",B11-D11)
A12: =IF(9<=Comparador!$B$6,9,"") | B12: =IF(A12="","",F11) | C12: =IF(A12="","",B12*Comparador!$B$12) | D12: =IF(A12="","",E12-C12) | E12: =IF(A12="","",Comparador!$B$13) | F12: =IF(A12="","",B12-D12)
A13: =IF(10<=Comparador!$B$6,10,"") | B13: =IF(A13="","",F12) | C13: =IF(A13="","",B13*Comparador!$B$12) | D13: =IF(A13="","",E13-C13) | E13: =IF(A13="","",Comparador!$B$13) | F13: =IF(A13="","",B13-D13)
A14: =IF(11<=Comparador!$B$6,11,"") | B14: =IF(A14="","",F13) | C14: =IF(A14="","",B14*Comparador!$B$12) | D14: =IF(A14="","",E14-C14) | E14: =IF(A14="","",Comparador!$B$13) | F14: =IF(A14="","",B14-D14)
A15: =IF(12<=Comparador!$B$6,12,"") | B15: =IF(A15="","",F14) | C15: =IF(A15="","",B15*Comparador!$B$12) | D15: =IF(A15="","",E15-C15) | E15: =IF(A15="","",Comparador!$B$13) | F15: =IF(A15="","",B15-D15)
A16: =IF(13<=Comparador!$B$6,13,"") | B16: =IF(A16="","",F15) | C16: =IF(A16="","",B16*Comparador!$B$12) | D16: =IF(A16="","",E16-C16) | E16: =IF(A16="","",Comparador!$B$13) | F16: =IF(A16="","",B16-D16)
A17: =IF(14<=Comparador!$B$6,14,"") | B17: =IF(A17="","",F16) | C17: =IF(A17="","",B17*Comparador!$B$12) | D17: =IF(A17="","",E17-C17) | E17: =IF(A17="","",Comparador!$B$13) | F17: =IF(A17="","",B17-D17)
A18: =IF(15<=Comparador!$B$6,15,"") | B18: =IF(A18="","",F17) | C18: =IF(A18="","",B18*Comparador!$B$12) | D18: =IF(A18="","",E18-C18) | E18: =IF(A18="","",Comparador!$B$13) | F18: =IF(A18="","",B18-D18)
A19: =IF(16<=Comparador!$B$6,16,"") | B19: =IF(A19="","",F18) | C19: =IF(A19="","",B19*Comparador!$B$12) | D19: =IF(A19="","",E19-C19) | E19: =IF(A19="","",Comparador!$B$13) | F19: =IF(A19="","",B19-D19)
A20: =IF(17<=Comparador!$B$6,17,"") | B20: =IF(A20="","",F19) | C20: =IF(A20="","",B20*Comparador!$B$12) | D20: =IF(A20="","",E20-C20) | E20: =IF(A20="","",Comparador!$B$13) | F20: =IF(A20="","",B20-D20)
A21: =IF(18<=Comparador!$B$6,18,"") | B21: =IF(A21="","",F20) | C21: =IF(A21="","",B21*Comparador!$B$12) | D21: =IF(A21="","",E21-C21) | E21: =IF(A21="","",Comparador!$B$13) | F21: =IF(A21="","",B21-D21)
A22: =IF(19<=Comparador!$B$6,19,"") | B22: =IF(A22="","",F21) | C22: =IF(A22="","",B22*Comparador!$B$12) | D22: =IF(A22="","",E22-C22) | E22: =IF(A22="","",Comparador!$B$13) | F22: =IF(A22="","",B22-D22)
A23: =IF(20<=Comparador!$B$6,20,"") | B23: =IF(A23="","",F22) | C23: =IF(A23="","",B23*Comparador!$B$12) | D23: =IF(A23="","",E23-C23) | E23: =IF(A23="","",Comparador!$B$13) | F23: =IF(A23="","",B23-D23)
A24: =IF(21<=Comparador!$B$6,21,"") | B24: =IF(A24="","",F23) | C24: =IF(A24="","",B24*Comparador!$B$12) | D24: =IF(A24="","",E24-C24) | E24: =IF(A24="","",Comparador!$B$13) | F24: =IF(A24="","",B24-D24)
A25: =IF(22<=Comparador!$B$6,22,"") | B25: =IF(A25="","",F24) | C25: =IF(A25="","",B25*Comparador!$B$12) | D25: =IF(A25="","",E25-C25) | E25: =IF(A25="","",Comparador!$B$13) | F25: =IF(A25="","",B25-D25)
A26: =IF(23<=Comparador!$B$6,23,"") | B26: =IF(A26="","",F25) | C26: =IF(A26="","",B26*Comparador!$B$12) | D26: =IF(A26="","",E26-C26) | E26: =IF(A26="","",Comparador!$B$13) | F26: =IF(A26="","",B26-D26)
A27: =IF(24<=Comparador!$B$6,24,"") | B27: =IF(A27="","",F26) | C27: =IF(A27="","",B27*Comparador!$B$12) | D27: =IF(A27="","",E27-C27) | E27: =IF(A27="","",Comparador!$B$13) | F27: =IF(A27="","",B27-D27)
A28: =IF(25<=Comparador!$B$6,25,"") | B28: =IF(A28="","",F27) | C28: =IF(A28="","",B28*Comparador!$B$12) | D28: =IF(A28="","",E28-C28) | E28: =IF(A28="","",Comparador!$B$13) | F28: =IF(A28="","",B28-D28)
A29: =IF(26<=Comparador!$B$6,26,"") | B29: =IF(A29="","",F28) | C29: =IF(A29="","",B29*Comparador!$B$12) | D29: =IF(A29="","",E29-C29) | E29: =IF(A29="","",Comparador!$B$13) | F29: =IF(A29="","",B29-D29)
A30: =IF(27<=Comparador!$B$6,27,"") | B30: =IF(A30="","",F29) | C30: =IF(A30="","",B30*Comparador!$B$12) | D30: =IF(A30="","",E30-C30) | E30: =IF(A30="","",Comparador!$B$13) | F30: =IF(A30="","",B30-D30)
A31: =IF(28<=Comparador!$B$6,28,"") | B31: =IF(A31="","",F30) | C31: =IF(A31="","",B31*Comparador!$B$12) | D31: =IF(A31="","",E31-C31) | E31: =IF(A31="","",Comparador!$B$13) | F31: =IF(A31="","",B31-D31)
A32: =IF(29<=Comparador!$B$6,29,"") | B32: =IF(A32="","",F31) | C32: =IF(A32="","",B32*Comparador!$B$12) | D32: =IF(A32="","",E32-C32) | E32: =IF(A32="","",Comparador!$B$13) | F32: =IF(A32="","",B32-D32)
A33: =IF(30<=Comparador!$B$6,30,"") | B33: =IF(A33="","",F32) | C33: =IF(A33="","",B33*Comparador!$B$12) | D33: =IF(A33="","",E33-C33) | E33: =IF(A33="","",Comparador!$B$13) | F33: =IF(A33="","",B33-D33)
A34: =IF(31<=Comparador!$B$6,31,"") | B34: =IF(A34="","",F33) | C34: =IF(A34="","",B34*Comparador!$B$12) | D34: =IF(A34="","",E34-C34) | E34: =IF(A34="","",Comparador!$B$13) | F34: =IF(A34="","",B34-D34)
A35: =IF(32<=Comparador!$B$6,32,"") | B35: =IF(A35="","",F34) | C35: =IF(A35="","",B35*Comparador!$B$12) | D35: =IF(A35="","",E35-C35) | E35: =IF(A35="","",Comparador!$B$13) | F35: =IF(A35="","",B35-D35)
A36: =IF(33<=Comparador!$B$6,33,"") | B36: =IF(A36="","",F35) | C36: =IF(A36="","",B36*Comparador!$B$12) | D36: =IF(A36="","",E36-C36) | E36: =IF(A36="","",Comparador!$B$13) | F36: =IF(A36="","",B36-D36)
A37: =IF(34<=Comparador!$B$6,34,"") | B37: =IF(A37="","",F36) | C37: =IF(A37="","",B37*Comparador!$B$12) | D37: =IF(A37="","",E37-C37) | E37: =IF(A37="","",Comparador!$B$13) | F37: =IF(A37="","",B37-D37)
A38: =IF(35<=Comparador!$B$6,35,"") | B38: =IF(A38="","",F37) | C38: =IF(A38="","",B38*Comparador!$B$12) | D38: =IF(A38="","",E38-C38) | E38: =IF(A38="","",Comparador!$B$13) | F38: =IF(A38="","",B38-D38)
A39: =IF(36<=Comparador!$B$6,36,"") | B39: =IF(A39="","",F38) | C39: =IF(A39="","",B39*Comparador!$B$12) | D39: =IF(A39="","",E39-C39) | E39: =IF(A39="","",Comparador!$B$13) | F39: =IF(A39="","",B39-D39)
A40: =IF(37<=Comparador!$B$6,37,"") | B40: =IF(A40="","",F39) | C40: =IF(A40="","",B40*Comparador!$B$12) | D40: =IF(A40="","",E40-C40) | E40: =IF(A40="","",Comparador!$B$13) | F40: =IF(A40="","",B40-D40)
A41: =IF(38<=Comparador!$B$6,38,"") | B41: =IF(A41="","",F40) | C41: =IF(A41="","",B41*Comparador!$B$12) | D41: =IF(A41="","",E41-C41) | E41: =IF(A41="","",Comparador!$B$13) | F41: =IF(A41="","",B41-D41)
...

Sheet Lista_de_preguntas
A1: PREGUNTAS ANTES DE FIRMAR (marca lo que ya verificaste)
A3: ¿La tasa que me dan es efectiva anual (E. A.) o nominal? ¿Cuál es el Valor Total Unificado del crédito? | B3: No
A4: ¿Hay seguro de vida o de deudor? ¿Es obligatorio, cuánto cuesta y puedo cotizarlo por mi cuenta? | B4: No
A5: ¿Hay comisión de estudio, de desembolso o cuota de manejo? ¿Se cobra al inicio o se financia? | B5: No
A6: ¿Puedo pagar antes sin penalidad? ¿Reduce la cuota o el plazo? | B6: No
A7: ¿Qué pasa si me atraso un mes? ¿Cuál es la tasa de mora y desde cuándo se cobra? | B7: No
A8: ¿La cuota es fija o cambia (tasa variable, DTF, IBR)? | B8: No
A9: ¿Qué reporta la entidad a las centrales de riesgo y cuándo? | B9: No
A10: ¿Qué pasa si pierdo el empleo? ¿Hay periodos de gracia o reestructuración? | B10: No
A11: ¿La cuota total cabe en mi presupuesto sin tocar lo esencial? | B11: No
A13: Preguntas resueltas | B13: =COUNTIF(B3:B11,"Sí")&" de "&COUNTA(A3:A11)
